# tests/test_fix_workflow.py
import pytest
import asyncio
from pathlib import Path
from typing import List
from unittest.mock import Mock, AsyncMock
from src.branch_fixer.services.git.repository import GitRepository

from src.branch_fixer.core.models import TestError, ErrorDetails, FixAttempt
from src.branch_fixer.orchestration.fix_service import FixService

# 1. Pre-Analysis Documentation
"""
Function Analysis:
- FixService.attempt_fix(error: TestError) -> bool
- Parameters: TestError instance
- Return: bool indicating success
- Async: Yes (uses AI calls)
- Dependencies: AIManager, TestRunner, ChangeApplier, GitRepo

Code Paths:
1. Happy Path: Create branch -> Generate fix -> Apply -> Test -> PR
2. Error - Branch Creation: Early return False
3. Error - AI Generation: Mark failed, raise
4. Error - Change Application: Mark failed, return False
5. Error - Test Verification: Retry with higher temp
6. Error - Max Retries: Return False

Infrastructure Needs:
- Async test support
- Mock all external services
- Git operation simulation
- Temporary file handling
"""


# 3. Basic Path Verification
class TestFixWorkflowPaths:
    """Verify each code path works correctly"""
    
    @pytest.mark.asyncio
    async def test_verify_happy_path(self, service_factory, error_factory):
        """Verify basic successful fix flow"""
        # Given
        service = service_factory()
        error = error_factory()
        
        # When 
        success = await service.attempt_fix(error)
        
        # Then
        assert success is True
        assert error.status == "fixed"
        # Verify path completion
        service.git_repo.create_branch.assert_called_once()
        service.ai_manager.generate_fix.assert_called_once()
        service.test_runner.run_test.assert_called_once()

    @pytest.mark.asyncio
    async def test_verify_branch_failure_path(self, service_factory, error_factory):
        """Verify early return on branch creation failure"""
        # Given
        service = service_factory(branch_success=False)
        error = error_factory()
        
        # When
        success = await service.attempt_fix(error)
        
        # Then
        assert success is False
        assert error.status == "unfixed"
        # Verify early exit
        service.ai_manager.generate_fix.assert_not_called()

    # Additional path verification tests...

# 4. Error Cases
class TestFixWorkflowErrors:
    """Verify error handling behavior"""
    
    @pytest.mark.asyncio 
    async def test_handles_ai_errors(self, service_factory, error_factory):
        """Verify AI error handling"""
        # Given
        service = service_factory()
        service.ai_manager.generate_fix.side_effect = Exception("AI Failed")
        error = error_factory()
        
        # When/Then
        with pytest.raises(Exception) as exc:
            await service.attempt_fix(error)
        
        # Verify proper error handling
        assert error.status == "unfixed"
        assert len(error.fix_attempts) == 1
        assert error.fix_attempts[0].status == "failed"

    # Additional error case tests...

# 5. Coverage Verification
"""Coverage Requirements:
- Branch Coverage: All decision points in attempt_fix
- Path Coverage: All possible combinations of success/failure
- Error Coverage: All exception handlers tested
"""
